Namespace(processes=2, use_gdc=False)
Processes: 2
tensor([[2.2999, 2.0972, 2.0375,  ..., 2.0575, 1.8973, 1.9199],
        [1.1355, 1.1036, 0.8721,  ..., 0.9138, 0.9111, 1.3782],
        [0.4661, 0.4388, 0.4750,  ..., 0.4863, 0.4685, 0.4839],
        ...,
        [0.0000, 0.0000, 0.0000,  ..., 0.0000, 0.0000, 0.0000],
        [0.0000, 0.0000, 0.0000,  ..., 0.0000, 0.0000, 0.0000],
        [0.0000, 0.0000, 0.0000,  ..., 0.0000, 0.0000, 0.0000]])
tensor([[ 84.2440, 106.2525,  48.8750,  ...,  67.3671, 110.9248,  96.8973],
        [ 66.7337,  85.8885,  40.1189,  ...,  54.6149,  88.3994,  78.2549],
        [  4.0454,   5.2127,   2.3081,  ...,   3.2400,   5.4090,   4.7005],
        ...,
        [  0.0000,   0.0000,   0.0000,  ...,   0.0000,   0.0000,   0.0000],
        [  0.0000,   0.0000,   0.0000,  ...,   0.0000,   0.0000,   0.0000],
        [  0.0000,   0.0000,   0.0000,  ...,   0.0000,   0.0000,   0.0000]])
Process Process-2:
Traceback (most recent call last):
  File "/global/home/users/alokt/.conda/envs/gcn/lib/python3.7/multiprocessing/process.py", line 297, in _bootstrap
    self.run()
  File "/global/home/users/alokt/.conda/envs/gcn/lib/python3.7/multiprocessing/process.py", line 99, in run
    self._target(*self._args, **self._kwargs)
  File "gcn_distr.py", line 174, in init_process
    fn(rank, size, inputs, weight1, weight2, adj_matrix, optimizer, data)
  File "gcn_distr.py", line 161, in run
    outputs = train(inputs_loc, weight1, weight2, adj_matrix_loc, optimizer, data, rank, size)
  File "gcn_distr.py", line 111, in train
    loss = F.nll_loss(outputs[data.train_mask], data.y[data.train_mask])
IndexError: The shape of the mask [2708] at index 0does not match the shape of the indexed tensor [1354, 7] at index 0
tensor([[1.4911, 1.4546, 1.6780,  ..., 1.4236, 1.5675, 1.5197],
        [1.5928, 1.6527, 1.4825,  ..., 1.5660, 1.5105, 1.7505],
        [2.7541, 2.9561, 2.7424,  ..., 2.5819, 2.3786, 2.6228],
        ...,
        [0.6375, 0.6456, 0.5668,  ..., 0.6305, 0.5032, 0.6677],
        [2.2268, 2.0960, 1.9800,  ..., 1.8888, 2.1974, 2.0595],
        [2.2841, 2.2451, 2.1333,  ..., 2.0271, 1.9916, 2.0250]])
tensor([[ 42.2983,  53.8474,  24.6189,  ...,  34.0478,  55.2591,  48.4371],
        [ 34.3444,  44.1953,  20.8759,  ...,  28.0574,  45.6028,  40.2090],
        [335.0311, 427.1190, 196.9960,  ..., 270.2451, 441.7349, 386.9506],
        ...,
        [  4.2215,   5.5692,   2.4970,  ...,   3.4455,   5.6738,   4.9559],
        [ 59.1088,  76.0076,  34.5847,  ...,  47.7643,  77.4707,  68.7087],
        [189.3287, 241.9992, 110.9998,  ..., 152.2920, 249.5821, 219.3261]])
tensor([[ 42.2983,  53.8474,  24.6189,  ...,  34.0478,  55.2591,  48.4371],
        [ 34.3444,  44.1953,  20.8759,  ...,  28.0574,  45.6028,  40.2090],
        [335.0311, 427.1190, 196.9960,  ..., 270.2451, 441.7349, 386.9506],
        ...,
        [172.1553, 221.3383, 102.7749,  ..., 139.6734, 227.1635, 199.6728],
        [ 16.9040,  22.3745,  10.5160,  ...,  13.8883,  22.6988,  20.0765],
        [ 75.4102,  96.0262,  44.8130,  ...,  61.0655,  99.0124,  88.2955]],
       grad_fn=<GCNFuncBackward>)
torch.Size([1354, 7])
Process Process-1:
Traceback (most recent call last):
  File "/global/home/users/alokt/.conda/envs/gcn/lib/python3.7/multiprocessing/process.py", line 297, in _bootstrap
    self.run()
  File "/global/home/users/alokt/.conda/envs/gcn/lib/python3.7/multiprocessing/process.py", line 99, in run
    self._target(*self._args, **self._kwargs)
  File "gcn_distr.py", line 174, in init_process
    fn(rank, size, inputs, weight1, weight2, adj_matrix, optimizer, data)
  File "gcn_distr.py", line 161, in run
    outputs = train(inputs_loc, weight1, weight2, adj_matrix_loc, optimizer, data, rank, size)
  File "gcn_distr.py", line 111, in train
    loss = F.nll_loss(outputs[data.train_mask], data.y[data.train_mask])
IndexError: The shape of the mask [2708] at index 0does not match the shape of the indexed tensor [1354, 7] at index 0
